[2025-10-23T22:26:28.011+0000] {local_task_job_runner.py:123} INFO - ::group::Pre task execution logs
[2025-10-23T22:26:28.017+0000] {taskinstance.py:2614} INFO - Dependencies all met for dep_context=non-requeueable deps ti=<TaskInstance: etl_pipeline.run_etl manual__2025-10-23T22:21:25.579221+00:00 [queued]>
[2025-10-23T22:26:28.019+0000] {taskinstance.py:2614} INFO - Dependencies all met for dep_context=requeueable deps ti=<TaskInstance: etl_pipeline.run_etl manual__2025-10-23T22:21:25.579221+00:00 [queued]>
[2025-10-23T22:26:28.019+0000] {taskinstance.py:2867} INFO - Starting attempt 2 of 2
[2025-10-23T22:26:28.023+0000] {taskinstance.py:2890} INFO - Executing <Task(DockerOperator): run_etl> on 2025-10-23 22:21:25.579221+00:00
[2025-10-23T22:26:28.029+0000] {standard_task_runner.py:104} INFO - Running: ['***', 'tasks', 'run', 'etl_pipeline', 'run_etl', 'manual__2025-10-23T22:21:25.579221+00:00', '--job-id', '14', '--raw', '--subdir', 'DAGS_FOLDER/etl_dag.py', '--cfg-path', '/tmp/tmpqttgtz4r']
[2025-10-23T22:26:28.031+0000] {standard_task_runner.py:105} INFO - Job 14: Subtask run_etl
[2025-10-23T22:26:28.030+0000] {logging_mixin.py:190} WARNING - /home/***/.local/lib/python3.12/site-packages/***/task/task_runner/standard_task_runner.py:70 DeprecationWarning: This process (pid=51670) is multi-threaded, use of fork() may lead to deadlocks in the child.
[2025-10-23T22:26:28.032+0000] {standard_task_runner.py:72} INFO - Started process 51671 to run task
[2025-10-23T22:26:28.052+0000] {task_command.py:467} INFO - Running <TaskInstance: etl_pipeline.run_etl manual__2025-10-23T22:21:25.579221+00:00 [running]> on host 596fdc9a152e
[2025-10-23T22:26:28.079+0000] {taskinstance.py:3134} INFO - Exporting env vars: AIRFLOW_CTX_DAG_OWNER='***' AIRFLOW_CTX_DAG_ID='etl_pipeline' AIRFLOW_CTX_TASK_ID='run_etl' AIRFLOW_CTX_EXECUTION_DATE='2025-10-23T22:21:25.579221+00:00' AIRFLOW_CTX_TRY_NUMBER='2' AIRFLOW_CTX_DAG_RUN_ID='manual__2025-10-23T22:21:25.579221+00:00'
[2025-10-23T22:26:28.079+0000] {logging_mixin.py:190} INFO - Task instance is in running state
[2025-10-23T22:26:28.079+0000] {logging_mixin.py:190} INFO -  Previous state of the Task instance: queued
[2025-10-23T22:26:28.080+0000] {logging_mixin.py:190} INFO - Current task name:run_etl state:running start_date:2025-10-23 22:26:28.017880+00:00
[2025-10-23T22:26:28.080+0000] {logging_mixin.py:190} INFO - Dag name:etl_pipeline and current dag run status:running
[2025-10-23T22:26:28.080+0000] {taskinstance.py:732} INFO - ::endgroup::
[2025-10-23T22:26:28.102+0000] {docker.py:345} INFO - Starting docker container from image etl_image
[2025-10-23T22:26:28.585+0000] {docker.py:69} INFO - Traceback (most recent call last):
[2025-10-23T22:26:28.585+0000] {docker.py:69} INFO -   File "/app/extract.py", line 9, in <module>
[2025-10-23T22:26:28.585+0000] {docker.py:69} INFO -     from scripts_etl.load import load_to_postgresql
[2025-10-23T22:26:28.585+0000] {docker.py:69} INFO - ModuleNotFoundError: No module named 'scripts_etl'
[2025-10-23T22:26:28.717+0000] {taskinstance.py:3313} ERROR - Task failed with exception
Traceback (most recent call last):
  File "/home/airflow/.local/lib/python3.12/site-packages/airflow/models/taskinstance.py", line 763, in _execute_task
    result = _execute_callable(context=context, **execute_callable_kwargs)
             ^^^^^^^^^^^^^^^^^^^^^^^^^^^^^^^^^^^^^^^^^^^^^^^^^^^^^^^^^^^^^
  File "/home/airflow/.local/lib/python3.12/site-packages/airflow/models/taskinstance.py", line 734, in _execute_callable
    return ExecutionCallableRunner(
           ^^^^^^^^^^^^^^^^^^^^^^^^
  File "/home/airflow/.local/lib/python3.12/site-packages/airflow/utils/operator_helpers.py", line 252, in run
    return self.func(*args, **kwargs)
           ^^^^^^^^^^^^^^^^^^^^^^^^^^
  File "/home/airflow/.local/lib/python3.12/site-packages/airflow/models/baseoperator.py", line 424, in wrapper
    return func(self, *args, **kwargs)
           ^^^^^^^^^^^^^^^^^^^^^^^^^^^
  File "/home/airflow/.local/lib/python3.12/site-packages/airflow/providers/docker/operators/docker.py", line 485, in execute
    return self._run_image()
           ^^^^^^^^^^^^^^^^^
  File "/home/airflow/.local/lib/python3.12/site-packages/airflow/providers/docker/operators/docker.py", line 362, in _run_image
    return self._run_image_with_mounts(self.mounts, add_tmp_variable=False)
           ^^^^^^^^^^^^^^^^^^^^^^^^^^^^^^^^^^^^^^^^^^^^^^^^^^^^^^^^^^^^^^^^
  File "/home/airflow/.local/lib/python3.12/site-packages/airflow/providers/docker/operators/docker.py", line 419, in _run_image_with_mounts
    raise DockerContainerFailedException(f"Docker container failed: {result!r}", logs=log_lines)
airflow.providers.docker.exceptions.DockerContainerFailedException: Docker container failed: {'StatusCode': 1}
[2025-10-23T22:26:28.719+0000] {logging_mixin.py:190} INFO - Task instance in failure state
[2025-10-23T22:26:28.719+0000] {logging_mixin.py:190} INFO - Task start:2025-10-23 22:26:28.017880+00:00 end:2025-10-23 22:26:28.719197+00:00 duration:0.701317
[2025-10-23T22:26:28.719+0000] {logging_mixin.py:190} INFO - Task:<Task(DockerOperator): run_etl> dag:<DAG: etl_pipeline> dagrun:<DagRun etl_pipeline @ 2025-10-23 22:21:25.579221+00:00: manual__2025-10-23T22:21:25.579221+00:00, state:running, queued_at: 2025-10-23 22:21:25.603759+00:00. externally triggered: True>
[2025-10-23T22:26:28.719+0000] {logging_mixin.py:190} INFO - Failure caused by Docker container failed: {'StatusCode': 1}
[2025-10-23T22:26:28.719+0000] {taskinstance.py:1226} INFO - Marking task as FAILED. dag_id=etl_pipeline, task_id=run_etl, run_id=manual__2025-10-23T22:21:25.579221+00:00, execution_date=20251023T222125, start_date=20251023T222628, end_date=20251023T222628
[2025-10-23T22:26:28.733+0000] {taskinstance.py:341} INFO - ::group::Post task execution logs
[2025-10-23T22:26:28.734+0000] {standard_task_runner.py:124} ERROR - Failed to execute job 14 for task run_etl (Docker container failed: {'StatusCode': 1}; 51671)
Traceback (most recent call last):
  File "/home/airflow/.local/lib/python3.12/site-packages/airflow/task/task_runner/standard_task_runner.py", line 117, in _start_by_fork
    ret = args.func(args, dag=self.dag)
          ^^^^^^^^^^^^^^^^^^^^^^^^^^^^^
  File "/home/airflow/.local/lib/python3.12/site-packages/airflow/cli/cli_config.py", line 49, in command
    return func(*args, **kwargs)
           ^^^^^^^^^^^^^^^^^^^^^
  File "/home/airflow/.local/lib/python3.12/site-packages/airflow/utils/cli.py", line 116, in wrapper
    return f(*args, **kwargs)
           ^^^^^^^^^^^^^^^^^^
  File "/home/airflow/.local/lib/python3.12/site-packages/airflow/cli/commands/task_command.py", line 483, in task_run
    task_return_code = _run_task_by_selected_method(args, _dag, ti)
                       ^^^^^^^^^^^^^^^^^^^^^^^^^^^^^^^^^^^^^^^^^^^^
  File "/home/airflow/.local/lib/python3.12/site-packages/airflow/cli/commands/task_command.py", line 256, in _run_task_by_selected_method
    return _run_raw_task(args, ti)
           ^^^^^^^^^^^^^^^^^^^^^^^
  File "/home/airflow/.local/lib/python3.12/site-packages/airflow/cli/commands/task_command.py", line 341, in _run_raw_task
    return ti._run_raw_task(
           ^^^^^^^^^^^^^^^^^
  File "/home/airflow/.local/lib/python3.12/site-packages/airflow/utils/session.py", line 97, in wrapper
    return func(*args, session=session, **kwargs)
           ^^^^^^^^^^^^^^^^^^^^^^^^^^^^^^^^^^^^^^
  File "/home/airflow/.local/lib/python3.12/site-packages/airflow/models/taskinstance.py", line 3006, in _run_raw_task
    return _run_raw_task(
           ^^^^^^^^^^^^^^
  File "/home/airflow/.local/lib/python3.12/site-packages/airflow/models/taskinstance.py", line 274, in _run_raw_task
    TaskInstance._execute_task_with_callbacks(
  File "/home/airflow/.local/lib/python3.12/site-packages/airflow/models/taskinstance.py", line 3161, in _execute_task_with_callbacks
    result = self._execute_task(context, task_orig)
             ^^^^^^^^^^^^^^^^^^^^^^^^^^^^^^^^^^^^^^
  File "/home/airflow/.local/lib/python3.12/site-packages/airflow/models/taskinstance.py", line 3185, in _execute_task
    return _execute_task(self, context, task_orig)
           ^^^^^^^^^^^^^^^^^^^^^^^^^^^^^^^^^^^^^^^
  File "/home/airflow/.local/lib/python3.12/site-packages/airflow/models/taskinstance.py", line 763, in _execute_task
    result = _execute_callable(context=context, **execute_callable_kwargs)
             ^^^^^^^^^^^^^^^^^^^^^^^^^^^^^^^^^^^^^^^^^^^^^^^^^^^^^^^^^^^^^
  File "/home/airflow/.local/lib/python3.12/site-packages/airflow/models/taskinstance.py", line 734, in _execute_callable
    return ExecutionCallableRunner(
           ^^^^^^^^^^^^^^^^^^^^^^^^
  File "/home/airflow/.local/lib/python3.12/site-packages/airflow/utils/operator_helpers.py", line 252, in run
    return self.func(*args, **kwargs)
           ^^^^^^^^^^^^^^^^^^^^^^^^^^
  File "/home/airflow/.local/lib/python3.12/site-packages/airflow/models/baseoperator.py", line 424, in wrapper
    return func(self, *args, **kwargs)
           ^^^^^^^^^^^^^^^^^^^^^^^^^^^
  File "/home/airflow/.local/lib/python3.12/site-packages/airflow/providers/docker/operators/docker.py", line 485, in execute
    return self._run_image()
           ^^^^^^^^^^^^^^^^^
  File "/home/airflow/.local/lib/python3.12/site-packages/airflow/providers/docker/operators/docker.py", line 362, in _run_image
    return self._run_image_with_mounts(self.mounts, add_tmp_variable=False)
           ^^^^^^^^^^^^^^^^^^^^^^^^^^^^^^^^^^^^^^^^^^^^^^^^^^^^^^^^^^^^^^^^
  File "/home/airflow/.local/lib/python3.12/site-packages/airflow/providers/docker/operators/docker.py", line 419, in _run_image_with_mounts
    raise DockerContainerFailedException(f"Docker container failed: {result!r}", logs=log_lines)
airflow.providers.docker.exceptions.DockerContainerFailedException: Docker container failed: {'StatusCode': 1}
[2025-10-23T22:26:28.749+0000] {local_task_job_runner.py:266} INFO - Task exited with return code 1
[2025-10-23T22:26:28.757+0000] {taskinstance.py:3901} INFO - 0 downstream tasks scheduled from follow-on schedule check
[2025-10-23T22:26:28.757+0000] {local_task_job_runner.py:245} INFO - ::endgroup::
