[2025-10-24T01:44:32.540+0000] {local_task_job_runner.py:123} INFO - ::group::Pre task execution logs
[2025-10-24T01:44:32.551+0000] {taskinstance.py:2614} INFO - Dependencies all met for dep_context=non-requeueable deps ti=<TaskInstance: etl_pipeline.run_etl scheduled__2025-10-23T00:00:00+00:00 [queued]>
[2025-10-24T01:44:32.554+0000] {taskinstance.py:2614} INFO - Dependencies all met for dep_context=requeueable deps ti=<TaskInstance: etl_pipeline.run_etl scheduled__2025-10-23T00:00:00+00:00 [queued]>
[2025-10-24T01:44:32.554+0000] {taskinstance.py:2867} INFO - Starting attempt 2 of 2
[2025-10-24T01:44:32.559+0000] {taskinstance.py:2890} INFO - Executing <Task(DockerOperator): run_etl> on 2025-10-23 00:00:00+00:00
[2025-10-24T01:44:32.566+0000] {standard_task_runner.py:104} INFO - Running: ['***', 'tasks', 'run', 'etl_pipeline', 'run_etl', 'scheduled__2025-10-23T00:00:00+00:00', '--job-id', '32', '--raw', '--subdir', 'DAGS_FOLDER/etl_dag.py', '--cfg-path', '/tmp/tmp091jjhe1']
[2025-10-24T01:44:32.567+0000] {standard_task_runner.py:105} INFO - Job 32: Subtask run_etl
[2025-10-24T01:44:32.567+0000] {logging_mixin.py:190} WARNING - /home/***/.local/lib/python3.12/site-packages/***/task/task_runner/standard_task_runner.py:70 DeprecationWarning: This process (pid=5544) is multi-threaded, use of fork() may lead to deadlocks in the child.
[2025-10-24T01:44:32.568+0000] {standard_task_runner.py:72} INFO - Started process 5610 to run task
[2025-10-24T01:44:32.593+0000] {task_command.py:467} INFO - Running <TaskInstance: etl_pipeline.run_etl scheduled__2025-10-23T00:00:00+00:00 [running]> on host bc4c527e0aef
[2025-10-24T01:44:32.626+0000] {taskinstance.py:3134} INFO - Exporting env vars: AIRFLOW_CTX_DAG_OWNER='***' AIRFLOW_CTX_DAG_ID='etl_pipeline' AIRFLOW_CTX_TASK_ID='run_etl' AIRFLOW_CTX_EXECUTION_DATE='2025-10-23T00:00:00+00:00' AIRFLOW_CTX_TRY_NUMBER='2' AIRFLOW_CTX_DAG_RUN_ID='scheduled__2025-10-23T00:00:00+00:00'
[2025-10-24T01:44:32.627+0000] {logging_mixin.py:190} INFO - Task instance is in running state
[2025-10-24T01:44:32.628+0000] {logging_mixin.py:190} INFO -  Previous state of the Task instance: queued
[2025-10-24T01:44:32.628+0000] {logging_mixin.py:190} INFO - Current task name:run_etl state:running start_date:2025-10-24 01:44:32.551582+00:00
[2025-10-24T01:44:32.628+0000] {logging_mixin.py:190} INFO - Dag name:etl_pipeline and current dag run status:running
[2025-10-24T01:44:32.628+0000] {taskinstance.py:732} INFO - ::endgroup::
[2025-10-24T01:44:32.652+0000] {docker.py:345} INFO - Starting docker container from image etl_image
[2025-10-24T01:44:33.225+0000] {docker.py:69} INFO - 
[2025-10-24T01:44:33.226+0000] {docker.py:69} INFO - === Scraping des entreprises du CAC 40 ===
[2025-10-24T01:44:34.398+0000] {docker.py:69} INFO - 
[2025-10-24T01:44:34.399+0000] {docker.py:69} INFO - Suivi des cours pour 40 entreprises
[2025-10-24T02:34:18.115+0000] {job.py:229} INFO - Heartbeat recovered after 2960.31 seconds
[2025-10-24T02:34:31.730+0000] {docker.py:69} INFO - Erreur pour STMPA: Failed to perform, curl: (28) Operation timed out after 30010 milliseconds with 0 bytes received. See https://curl.se/libcurl/c/libcurl-errors.html first for more details.
[2025-10-24T02:49:50.112+0000] {job.py:229} INFO - Heartbeat recovered after 906.71 seconds
[2025-10-24T02:50:21.702+0000] {docker.py:69} INFO - Erreur pour HO: Failed to perform, curl: (28) Operation timed out after 30012 milliseconds with 0 bytes received. See https://curl.se/libcurl/c/libcurl-errors.html first for more details.
[2025-10-24T02:50:45.176+0000] {docker.py:69} INFO - 
[2025-10-24T02:50:45.178+0000] {docker.py:69} INFO - Erreur inattendue: non convertible value N/A with the unit 's', at position 34
[2025-10-24T02:50:45.181+0000] {docker.py:69} INFO - Traceback (most recent call last):
[2025-10-24T02:50:45.181+0000] {docker.py:69} INFO -   File "pandas/_libs/tslib.pyx", line 316, in pandas._libs.tslib.array_with_unit_to_datetime
[2025-10-24T02:50:45.182+0000] {docker.py:69} INFO - ValueError: could not convert string to float: 'N/A'
[2025-10-24T02:50:45.182+0000] {docker.py:69} INFO - 
[2025-10-24T02:50:45.183+0000] {docker.py:69} INFO - During handling of the above exception, another exception occurred:
[2025-10-24T02:50:45.183+0000] {docker.py:69} INFO - 
[2025-10-24T02:50:45.183+0000] {docker.py:69} INFO - Traceback (most recent call last):
[2025-10-24T02:50:45.184+0000] {docker.py:69} INFO -   File "/app/extract.py", line 119, in <module>
[2025-10-24T02:50:45.184+0000] {docker.py:69} INFO -     asyncio.run(main())
[2025-10-24T02:50:45.184+0000] {docker.py:69} INFO -   File "/usr/local/lib/python3.9/asyncio/runners.py", line 44, in run
[2025-10-24T02:50:45.184+0000] {docker.py:69} INFO -     return loop.run_until_complete(main)
[2025-10-24T02:50:45.185+0000] {docker.py:69} INFO -   File "/usr/local/lib/python3.9/asyncio/base_events.py", line 647, in run_until_complete
[2025-10-24T02:50:45.185+0000] {docker.py:69} INFO -     return future.result()
[2025-10-24T02:50:45.186+0000] {docker.py:69} INFO -   File "/app/extract.py", line 115, in main
[2025-10-24T02:50:45.186+0000] {docker.py:69} INFO -     raise e
[2025-10-24T02:50:45.186+0000] {docker.py:69} INFO -   File "/app/extract.py", line 106, in main
[2025-10-24T02:50:45.186+0000] {docker.py:69} INFO -     transformed_data = transform(stock_prices)
[2025-10-24T02:50:45.186+0000] {docker.py:69} INFO -   File "/app/transform.py", line 17, in transform
[2025-10-24T02:50:45.187+0000] {docker.py:69} INFO -     df["date"] = pd.to_datetime(df["date"], unit="s")
[2025-10-24T02:50:45.187+0000] {docker.py:69} INFO -   File "/usr/local/lib/python3.9/site-packages/pandas/core/tools/datetimes.py", line 1072, in to_datetime
[2025-10-24T02:50:45.187+0000] {docker.py:69} INFO -     values = convert_listlike(arg._values, format)
[2025-10-24T02:50:45.187+0000] {docker.py:69} INFO -   File "/usr/local/lib/python3.9/site-packages/pandas/core/tools/datetimes.py", line 409, in _convert_listlike_datetimes
[2025-10-24T02:50:45.187+0000] {docker.py:69} INFO -     return _to_datetime_with_unit(arg, unit, name, utc, errors)
[2025-10-24T02:50:45.187+0000] {docker.py:69} INFO -   File "/usr/local/lib/python3.9/site-packages/pandas/core/tools/datetimes.py", line 531, in _to_datetime_with_unit
[2025-10-24T02:50:45.188+0000] {docker.py:69} INFO -     arr, tz_parsed = tslib.array_with_unit_to_datetime(arg, unit, errors=errors)
[2025-10-24T02:50:45.188+0000] {docker.py:69} INFO -   File "pandas/_libs/tslib.pyx", line 344, in pandas._libs.tslib.array_with_unit_to_datetime
[2025-10-24T02:50:45.188+0000] {docker.py:69} INFO -   File "pandas/_libs/tslib.pyx", line 318, in pandas._libs.tslib.array_with_unit_to_datetime
[2025-10-24T02:50:45.188+0000] {docker.py:69} INFO - ValueError: non convertible value N/A with the unit 's', at position 34
[2025-10-24T02:50:45.501+0000] {taskinstance.py:3313} ERROR - Task failed with exception
Traceback (most recent call last):
  File "/home/airflow/.local/lib/python3.12/site-packages/airflow/models/taskinstance.py", line 763, in _execute_task
    result = _execute_callable(context=context, **execute_callable_kwargs)
             ^^^^^^^^^^^^^^^^^^^^^^^^^^^^^^^^^^^^^^^^^^^^^^^^^^^^^^^^^^^^^
  File "/home/airflow/.local/lib/python3.12/site-packages/airflow/models/taskinstance.py", line 734, in _execute_callable
    return ExecutionCallableRunner(
           ^^^^^^^^^^^^^^^^^^^^^^^^
  File "/home/airflow/.local/lib/python3.12/site-packages/airflow/utils/operator_helpers.py", line 252, in run
    return self.func(*args, **kwargs)
           ^^^^^^^^^^^^^^^^^^^^^^^^^^
  File "/home/airflow/.local/lib/python3.12/site-packages/airflow/models/baseoperator.py", line 424, in wrapper
    return func(self, *args, **kwargs)
           ^^^^^^^^^^^^^^^^^^^^^^^^^^^
  File "/home/airflow/.local/lib/python3.12/site-packages/airflow/providers/docker/operators/docker.py", line 485, in execute
    return self._run_image()
           ^^^^^^^^^^^^^^^^^
  File "/home/airflow/.local/lib/python3.12/site-packages/airflow/providers/docker/operators/docker.py", line 362, in _run_image
    return self._run_image_with_mounts(self.mounts, add_tmp_variable=False)
           ^^^^^^^^^^^^^^^^^^^^^^^^^^^^^^^^^^^^^^^^^^^^^^^^^^^^^^^^^^^^^^^^
  File "/home/airflow/.local/lib/python3.12/site-packages/airflow/providers/docker/operators/docker.py", line 419, in _run_image_with_mounts
    raise DockerContainerFailedException(f"Docker container failed: {result!r}", logs=log_lines)
airflow.providers.docker.exceptions.DockerContainerFailedException: Docker container failed: {'StatusCode': 1}
[2025-10-24T02:50:45.507+0000] {logging_mixin.py:190} INFO - Task instance in failure state
[2025-10-24T02:50:45.507+0000] {logging_mixin.py:190} INFO - Task start:2025-10-24 01:44:32.551582+00:00 end:2025-10-24 02:50:45.505375+00:00 duration:3972.953793
[2025-10-24T02:50:45.508+0000] {logging_mixin.py:190} INFO - Task:<Task(DockerOperator): run_etl> dag:<DAG: etl_pipeline> dagrun:<DagRun etl_pipeline @ 2025-10-23 00:00:00+00:00: scheduled__2025-10-23T00:00:00+00:00, state:running, queued_at: 2025-10-24 00:37:00.955193+00:00. externally triggered: False>
[2025-10-24T02:50:45.508+0000] {logging_mixin.py:190} INFO - Failure caused by Docker container failed: {'StatusCode': 1}
[2025-10-24T02:50:45.508+0000] {taskinstance.py:1226} INFO - Marking task as FAILED. dag_id=etl_pipeline, task_id=run_etl, run_id=scheduled__2025-10-23T00:00:00+00:00, execution_date=20251023T000000, start_date=20251024T014432, end_date=20251024T025045
[2025-10-24T02:50:45.528+0000] {taskinstance.py:341} INFO - ::group::Post task execution logs
[2025-10-24T02:50:45.528+0000] {standard_task_runner.py:124} ERROR - Failed to execute job 32 for task run_etl (Docker container failed: {'StatusCode': 1}; 5610)
Traceback (most recent call last):
  File "/home/airflow/.local/lib/python3.12/site-packages/airflow/task/task_runner/standard_task_runner.py", line 117, in _start_by_fork
    ret = args.func(args, dag=self.dag)
          ^^^^^^^^^^^^^^^^^^^^^^^^^^^^^
  File "/home/airflow/.local/lib/python3.12/site-packages/airflow/cli/cli_config.py", line 49, in command
    return func(*args, **kwargs)
           ^^^^^^^^^^^^^^^^^^^^^
  File "/home/airflow/.local/lib/python3.12/site-packages/airflow/utils/cli.py", line 116, in wrapper
    return f(*args, **kwargs)
           ^^^^^^^^^^^^^^^^^^
  File "/home/airflow/.local/lib/python3.12/site-packages/airflow/cli/commands/task_command.py", line 483, in task_run
    task_return_code = _run_task_by_selected_method(args, _dag, ti)
                       ^^^^^^^^^^^^^^^^^^^^^^^^^^^^^^^^^^^^^^^^^^^^
  File "/home/airflow/.local/lib/python3.12/site-packages/airflow/cli/commands/task_command.py", line 256, in _run_task_by_selected_method
    return _run_raw_task(args, ti)
           ^^^^^^^^^^^^^^^^^^^^^^^
  File "/home/airflow/.local/lib/python3.12/site-packages/airflow/cli/commands/task_command.py", line 341, in _run_raw_task
    return ti._run_raw_task(
           ^^^^^^^^^^^^^^^^^
  File "/home/airflow/.local/lib/python3.12/site-packages/airflow/utils/session.py", line 97, in wrapper
    return func(*args, session=session, **kwargs)
           ^^^^^^^^^^^^^^^^^^^^^^^^^^^^^^^^^^^^^^
  File "/home/airflow/.local/lib/python3.12/site-packages/airflow/models/taskinstance.py", line 3006, in _run_raw_task
    return _run_raw_task(
           ^^^^^^^^^^^^^^
  File "/home/airflow/.local/lib/python3.12/site-packages/airflow/models/taskinstance.py", line 274, in _run_raw_task
    TaskInstance._execute_task_with_callbacks(
  File "/home/airflow/.local/lib/python3.12/site-packages/airflow/models/taskinstance.py", line 3161, in _execute_task_with_callbacks
    result = self._execute_task(context, task_orig)
             ^^^^^^^^^^^^^^^^^^^^^^^^^^^^^^^^^^^^^^
  File "/home/airflow/.local/lib/python3.12/site-packages/airflow/models/taskinstance.py", line 3185, in _execute_task
    return _execute_task(self, context, task_orig)
           ^^^^^^^^^^^^^^^^^^^^^^^^^^^^^^^^^^^^^^^
  File "/home/airflow/.local/lib/python3.12/site-packages/airflow/models/taskinstance.py", line 763, in _execute_task
    result = _execute_callable(context=context, **execute_callable_kwargs)
             ^^^^^^^^^^^^^^^^^^^^^^^^^^^^^^^^^^^^^^^^^^^^^^^^^^^^^^^^^^^^^
  File "/home/airflow/.local/lib/python3.12/site-packages/airflow/models/taskinstance.py", line 734, in _execute_callable
    return ExecutionCallableRunner(
           ^^^^^^^^^^^^^^^^^^^^^^^^
  File "/home/airflow/.local/lib/python3.12/site-packages/airflow/utils/operator_helpers.py", line 252, in run
    return self.func(*args, **kwargs)
           ^^^^^^^^^^^^^^^^^^^^^^^^^^
  File "/home/airflow/.local/lib/python3.12/site-packages/airflow/models/baseoperator.py", line 424, in wrapper
    return func(self, *args, **kwargs)
           ^^^^^^^^^^^^^^^^^^^^^^^^^^^
  File "/home/airflow/.local/lib/python3.12/site-packages/airflow/providers/docker/operators/docker.py", line 485, in execute
    return self._run_image()
           ^^^^^^^^^^^^^^^^^
  File "/home/airflow/.local/lib/python3.12/site-packages/airflow/providers/docker/operators/docker.py", line 362, in _run_image
    return self._run_image_with_mounts(self.mounts, add_tmp_variable=False)
           ^^^^^^^^^^^^^^^^^^^^^^^^^^^^^^^^^^^^^^^^^^^^^^^^^^^^^^^^^^^^^^^^
  File "/home/airflow/.local/lib/python3.12/site-packages/airflow/providers/docker/operators/docker.py", line 419, in _run_image_with_mounts
    raise DockerContainerFailedException(f"Docker container failed: {result!r}", logs=log_lines)
airflow.providers.docker.exceptions.DockerContainerFailedException: Docker container failed: {'StatusCode': 1}
[2025-10-24T02:50:45.544+0000] {local_task_job_runner.py:266} INFO - Task exited with return code 1
[2025-10-24T02:50:45.553+0000] {taskinstance.py:3901} INFO - 0 downstream tasks scheduled from follow-on schedule check
[2025-10-24T02:50:45.554+0000] {local_task_job_runner.py:245} INFO - ::endgroup::
